Traceback (most recent call last):
  File "/home/runner/workspace/.pythonlibs/lib/python3.11/site-packages/sqlalchemy/engine/base.py", line 1963, in _exec_single_context
    self.dialect.do_execute(
  File "/home/runner/workspace/.pythonlibs/lib/python3.11/site-packages/sqlalchemy/engine/default.py", line 943, in do_execute
    cursor.execute(statement, parameters)
psycopg2.errors.UndefinedColumn: column user.name does not exist
LINE 1: ...r".role AS user_role, "user".email AS user_email, "user".nam...
                                                             ^


The above exception was the direct cause of the following exception:

Traceback (most recent call last):
  File "/home/runner/workspace/.pythonlibs/lib/python3.11/site-packages/gunicorn/arbiter.py", line 608, in spawn_worker
    worker.init_process()
  File "/home/runner/workspace/.pythonlibs/lib/python3.11/site-packages/gunicorn/workers/base.py", line 135, in init_process
    self.load_wsgi()
  File "/home/runner/workspace/.pythonlibs/lib/python3.11/site-packages/gunicorn/workers/base.py", line 147, in load_wsgi
    self.wsgi = self.app.wsgi()
                ^^^^^^^^^^^^^^^
  File "/home/runner/workspace/.pythonlibs/lib/python3.11/site-packages/gunicorn/app/base.py", line 66, in wsgi
    self.callable = self.load()
                    ^^^^^^^^^^^
  File "/home/runner/workspace/.pythonlibs/lib/python3.11/site-packages/gunicorn/app/wsgiapp.py", line 57, in load
    return self.load_wsgiapp()
           ^^^^^^^^^^^^^^^^^^^
  File "/home/runner/workspace/.pythonlibs/lib/python3.11/site-packages/gunicorn/app/wsgiapp.py", line 47, in load_wsgiapp
    return util.import_app(self.app_uri)
           ^^^^^^^^^^^^^^^^^^^^^^^^^^^^^
  File "/home/runner/workspace/.pythonlibs/lib/python3.11/site-packages/gunicorn/util.py", line 370, in import_app
    mod = importlib.import_module(module)
          ^^^^^^^^^^^^^^^^^^^^^^^^^^^^^^^
  File "/nix/store/clx0mcir7qw8zk36zbr4jra789g3knf6-python3-3.11.10/lib/python3.11/importlib/__init__.py", line 126, in import_module
    return _bootstrap._gcd_import(name[level:], package, level)
           ^^^^^^^^^^^^^^^^^^^^^^^^^^^^^^^^^^^^^^^^^^^^^^^^^^^^
  File "<frozen importlib._bootstrap>", line 1204, in _gcd_import
  File "<frozen importlib._bootstrap>", line 1176, in _find_and_load
  File "<frozen importlib._bootstrap>", line 1147, in _find_and_load_unlocked
  File "<frozen importlib._bootstrap>", line 690, in _load_unlocked
  File "<frozen importlib._bootstrap_external>", line 940, in exec_module
  File "<frozen importlib._bootstrap>", line 241, in _call_with_frames_removed
  File "/home/runner/workspace/main.py", line 1, in <module>
    from app import app, socketio
  File "/home/runner/workspace/app.py", line 73, in <module>
    existing_user = User.query.filter_by(username=user_data["username"]).first()
                    ^^^^^^^^^^^^^^^^^^^^^^^^^^^^^^^^^^^^^^^^^^^^^^^^^^^^^^^^^^^^
  File "/home/runner/workspace/.pythonlibs/lib/python3.11/site-packages/sqlalchemy/orm/query.py", line 2759, in first
    return self.limit(1)._iter().first()  # type: ignore
           ^^^^^^^^^^^^^^^^^^^^^
  File "/home/runner/workspace/.pythonlibs/lib/python3.11/site-packages/sqlalchemy/orm/query.py", line 2857, in _iter
    result: Union[ScalarResult[_T], Result[_T]] = self.session.execute(
                                                  ^^^^^^^^^^^^^^^^^^^^^
  File "/home/runner/workspace/.pythonlibs/lib/python3.11/site-packages/sqlalchemy/orm/session.py", line 2365, in execute
    return self._execute_internal(
           ^^^^^^^^^^^^^^^^^^^^^^^
  File "/home/runner/workspace/.pythonlibs/lib/python3.11/site-packages/sqlalchemy/orm/session.py", line 2251, in _execute_internal
    result: Result[Any] = compile_state_cls.orm_execute_statement(
                          ^^^^^^^^^^^^^^^^^^^^^^^^^^^^^^^^^^^^^^^^
  File "/home/runner/workspace/.pythonlibs/lib/python3.11/site-packages/sqlalchemy/orm/context.py", line 306, in orm_execute_statement
    result = conn.execute(
             ^^^^^^^^^^^^^
  File "/home/runner/workspace/.pythonlibs/lib/python3.11/site-packages/sqlalchemy/engine/base.py", line 1415, in execute
    return meth(
           ^^^^^
  File "/home/runner/workspace/.pythonlibs/lib/python3.11/site-packages/sqlalchemy/sql/elements.py", line 523, in _execute_on_connection
    return connection._execute_clauseelement(
           ^^^^^^^^^^^^^^^^^^^^^^^^^^^^^^^^^^
  File "/home/runner/workspace/.pythonlibs/lib/python3.11/site-packages/sqlalchemy/engine/base.py", line 1637, in _execute_clauseelement
    ret = self._execute_context(
          ^^^^^^^^^^^^^^^^^^^^^^
  File "/home/runner/workspace/.pythonlibs/lib/python3.11/site-packages/sqlalchemy/engine/base.py", line 1842, in _execute_context
    return self._exec_single_context(
           ^^^^^^^^^^^^^^^^^^^^^^^^^^
  File "/home/runner/workspace/.pythonlibs/lib/python3.11/site-packages/sqlalchemy/engine/base.py", line 1982, in _exec_single_context
    self._handle_dbapi_exception(
  File "/home/runner/workspace/.pythonlibs/lib/python3.11/site-packages/sqlalchemy/engine/base.py", line 2351, in _handle_dbapi_exception
    raise sqlalchemy_exception.with_traceback(exc_info[2]) from e
  File "/home/runner/workspace/.pythonlibs/lib/python3.11/site-packages/sqlalchemy/engine/base.py", line 1963, in _exec_single_context
    self.dialect.do_execute(
  File "/home/runner/workspace/.pythonlibs/lib/python3.11/site-packages/sqlalchemy/engine/default.py", line 943, in do_execute
    cursor.execute(statement, parameters)
sqlalchemy.exc.ProgrammingError: (psycopg2.errors.UndefinedColumn) column user.name does not exist
LINE 1: ...r".role AS user_role, "user".email AS user_email, "user".nam...
                                                             ^

[SQL: SELECT "user".id AS user_id, "user".username AS user_username, "user".password_hash AS user_password_hash, "user".role AS user_role, "user".email AS user_email, "user".name AS user_name, "user".created_at AS user_created_at, "user".active AS user_active 
FROM "user" 
WHERE "user".username = %(username_1)s 
 LIMIT %(param_1)s]
[parameters: {'username_1': 'admin', 'param_1': 1}]
(Background on this error at: https://sqlalche.me/e/20/f405)
[2025-06-06 01:02:37 +0000] [147] [INFO] Worker exiting (pid: 147)
[2025-06-06 01:02:37 +0000] [136] [ERROR] Worker (pid:147) exited with code 3
[2025-06-06 01:02:37 +0000] [136] [ERROR] Shutting down: Master
[2025-06-06 01:02:37 +0000] [136] [ERROR] Reason: Worker failed to boot.